import { AxiosError } from 'axios';

// Types d'erreurs personnalis√©s
export enum ErrorType {
  NETWORK = 'NETWORK',
  VALIDATION = 'VALIDATION',
  AUTHENTICATION = 'AUTHENTICATION',
  AUTHORIZATION = 'AUTHORIZATION',
  NOT_FOUND = 'NOT_FOUND',
  SERVER = 'SERVER',
  UNKNOWN = 'UNKNOWN'
}

export interface AppError {
  type: ErrorType;
  message: string;
  details?: any;
  statusCode?: number;
  timestamp: string;
}

// Mapper les codes d'erreur HTTP aux types d'erreur
function getErrorType(statusCode?: number): ErrorType {
  if (!statusCode) return ErrorType.NETWORK;
  
  switch (statusCode) {
    case 400:
      return ErrorType.VALIDATION;
    case 401:
      return ErrorType.AUTHENTICATION;
    case 403:
      return ErrorType.AUTHORIZATION;
    case 404:
      return ErrorType.NOT_FOUND;
    case 500:
    case 502:
    case 503:
    case 504:
      return ErrorType.SERVER;
    default:
      return ErrorType.UNKNOWN;
  }
}

// Messages d'erreur user-friendly
const errorMessages: Record<ErrorType, string> = {
  [ErrorType.NETWORK]: 'Impossible de se connecter au serveur. V√©rifiez votre connexion internet.',
  [ErrorType.VALIDATION]: 'Les donn√©es fournies sont invalides. Veuillez v√©rifier et r√©essayer.',
  [ErrorType.AUTHENTICATION]: 'Vous devez vous connecter pour acc√©der √† cette ressource.',
  [ErrorType.AUTHORIZATION]: 'Vous n\'avez pas les permissions n√©cessaires pour cette action.',
  [ErrorType.NOT_FOUND]: 'La ressource demand√©e n\'existe pas.',
  [ErrorType.SERVER]: 'Une erreur serveur est survenue. Veuillez r√©essayer plus tard.',
  [ErrorType.UNKNOWN]: 'Une erreur inattendue est survenue.'
};

// Gestionnaire d'erreur principal
export function handleError(error: any): AppError {
  const timestamp = new Date().toISOString();

  // Erreur Axios
  if (error.isAxiosError) {
    const axiosError = error as AxiosError<any>;
    const statusCode = axiosError.response?.status;
    const type = getErrorType(statusCode);
    
    // Extraire le message d'erreur du backend si disponible
    let message = errorMessages[type];
    if (axiosError.response?.data?.detail) {
      message = axiosError.response.data.detail;
    } else if (axiosError.response?.data?.message) {
      message = axiosError.response.data.message;
    }

    return {
      type,
      message,
      details: axiosError.response?.data,
      statusCode,
      timestamp
    };
  }

  // Erreur JavaScript standard
  if (error instanceof Error) {
    return {
      type: ErrorType.UNKNOWN,
      message: error.message,
      details: error.stack,
      timestamp
    };
  }

  // Erreur inconnue
  return {
    type: ErrorType.UNKNOWN,
    message: typeof error === 'string' ? error : 'Une erreur inconnue est survenue',
    details: error,
    timestamp
  };
}

// Logger d'erreur (peut √™tre √©tendu pour envoyer √† un service externe)
export function logError(error: AppError): void {
  if (import.meta.env.DEV) {
    console.group(`üö® Error [${error.type}]`);
    console.error('Message:', error.message);
    console.error('Timestamp:', error.timestamp);
    if (error.details) {
      console.error('Details:', error.details);
    }
    if (error.statusCode) {
      console.error('Status Code:', error.statusCode);
    }
    console.groupEnd();
  }

  // En production, envoyer √† un service de monitoring
  if (import.meta.env.PROD) {
    // TODO: Int√©grer avec Sentry, LogRocket, etc.
    // window.Sentry?.captureException(error);
  }
}

// Retry logic pour les erreurs r√©seau
export async function retryWithBackoff<T>(
  fn: () => Promise<T>,
  maxRetries: number = 3,
  initialDelay: number = 1000
): Promise<T> {
  let lastError: any;
  
  for (let i = 0; i < maxRetries; i++) {
    try {
      return await fn();
    } catch (error) {
      lastError = error;
      
      // Ne pas r√©essayer pour certaines erreurs
      const appError = handleError(error);
      if ([
        ErrorType.VALIDATION,
        ErrorType.AUTHENTICATION,
        ErrorType.AUTHORIZATION,
        ErrorType.NOT_FOUND
      ].includes(appError.type)) {
        throw error;
      }
      
      // Attendre avant de r√©essayer avec backoff exponentiel
      if (i < maxRetries - 1) {
        const delay = initialDelay * Math.pow(2, i);
        await new Promise(resolve => setTimeout(resolve, delay));
      }
    }
  }
  
  throw lastError;
}

// Hook pour g√©rer les erreurs dans les composants
export function useApiError() {
  const [error, setError] = React.useState<AppError | null>(null);
  const [isRetrying, setIsRetrying] = React.useState(false);

  const handleApiError = React.useCallback((error: any) => {
    const appError = handleError(error);
    logError(appError);
    setError(appError);
    return appError;
  }, []);

  const clearError = React.useCallback(() => {
    setError(null);
  }, []);

  const retry = React.useCallback(async (fn: () => Promise<any>) => {
    setIsRetrying(true);
    clearError();
    
    try {
      const result = await retryWithBackoff(fn);
      return result;
    } catch (error) {
      handleApiError(error);
      throw error;
    } finally {
      setIsRetrying(false);
    }
  }, [handleApiError, clearError]);

  return {
    error,
    isRetrying,
    handleApiError,
    clearError,
    retry
  };
}

import React from 'react';